Workbook

Sheet README
A1: TPF Operational Readiness Score — Standards
A2: Generated 2026-05-11 · for Phase 12 review
A4: Tiers (4-level):
A5: Pass — PFT pass / official minimum
A6: Good — comfortable margin above PFT
A7: Excellent — what you actually need to be good at the job
A8: Elite — top decile · "top class soldier" territory
A10: Strength values: ABSOLUTE kg (not × BW). Same job demands the same load regardless of who is doing it.
A11: HBDL is ~10% higher than conventional DL across every pathway (Cholewa 2019; Camara 2016).
A13: Sheets:
A14: Standards — every (pathway, benchmark) row with all 4 tiers. Edit values here.
A15: Weights — component weight % per pathway. Must sum to 100.
... A33: See Standards col K "App status" for per-row provenance.

Sheet Standards
A1: Pathway | B1: Component | C1: Benchmark | D1: Unit | E1: Direction | F1: Pass | G1: Good | H1: Excellent | I1: Elite | J1: Notes | K1: App status
A2: UK Parachute Regiment (P Coy) | B2: lower_strength | C2: Back Squat | D2: kg | E2: higher-is-better | F2: =IFERROR(VLOOKUP("UK Parachute Regiment (P Coy)",'Strength by pathway'!$A:$AG,2,FALSE),"—") | G2: =IFERROR(VLOOKUP("UK Parachute Regiment (P Coy)",'Strength by pathway'!$A:$AG,3,FALSE),"—") | H2: =IFERROR(VLOOKUP("UK Parachute Regiment (P Coy)",'Strength by pathway'!$A:$AG,4,FALSE),"—") | I2: =IFERROR(VLOOKUP("UK Parachute Regiment (P Coy)",'Strength by pathway'!$A:$AG,5,FALSE),"—") | K2: synced 2026-05-21 from benchmark_tests.ts
A3: UK Parachute Regiment (P Coy) | B3: lower_strength | C3: Hex-bar DL | D3: kg | E3: higher-is-better | F3: =IFERROR(VLOOKUP("UK Parachute Regiment (P Coy)",'Strength by pathway'!$A:$AG,6,FALSE),"—") | G3: =IFERROR(VLOOKUP("UK Parachute Regiment (P Coy)",'Strength by pathway'!$A:$AG,7,FALSE),"—") | H3: =IFERROR(VLOOKUP("UK Parachute Regiment (P Coy)",'Strength by pathway'!$A:$AG,8,FALSE),"—") | I3: =IFERROR(VLOOKUP("UK Parachute Regiment (P Coy)",'Strength by pathway'!$A:$AG,9,FALSE),"—")
A4: UK Parachute Regiment (P Coy) | B4: lower_strength | C4: Conventional DL | D4: kg | E4: higher-is-better | F4: =IFERROR(VLOOKUP("UK Parachute Regiment (P Coy)",'Strength by pathway'!$A:$AG,10,FALSE),"—") | G4: =IFERROR(VLOOKUP("UK Parachute Regiment (P Coy)",'Strength by pathway'!$A:$AG,11,FALSE),"—") | H4: =IFERROR(VLOOKUP("UK Parachute Regiment (P Coy)",'Strength by pathway'!$A:$AG,12,FALSE),"—") | I4: =IFERROR(VLOOKUP("UK Parachute Regiment (P Coy)",'Strength by pathway'!$A:$AG,13,FALSE),"—")
A5: UK Parachute Regiment (P Coy) | B5: upper_strength | C5: Bench Press | D5: kg | E5: higher-is-better | F5: =IFERROR(VLOOKUP("UK Parachute Regiment (P Coy)",'Strength by pathway'!$A:$AG,14,FALSE),"—") | G5: =IFERROR(VLOOKUP("UK Parachute Regiment (P Coy)",'Strength by pathway'!$A:$AG,15,FALSE),"—") | H5: =IFERROR(VLOOKUP("UK Parachute Regiment (P Coy)",'Strength by pathway'!$A:$AG,16,FALSE),"—") | I5: =IFERROR(VLOOKUP("UK Parachute Regiment (P Coy)",'Strength by pathway'!$A:$AG,17,FALSE),"—")
A6: UK Parachute Regiment (P Coy) | B6: power | C6: Power Clean | D6: kg | E6: higher-is-better | F6: =IFERROR(VLOOKUP("UK Parachute Regiment (P Coy)",'Strength by pathway'!$A:$AG,22,FALSE),"—") | G6: =IFERROR(VLOOKUP("UK Parachute Regiment (P Coy)",'Strength by pathway'!$A:$AG,23,FALSE),"—") | H6: =IFERROR(VLOOKUP("UK Parachute Regiment (P Coy)",'Strength by pathway'!$A:$AG,24,FALSE),"—") | I6: =IFERROR(VLOOKUP("UK Parachute Regiment (P Coy)",'Strength by pathway'!$A:$AG,25,FALSE),"—")
A7: UK Parachute Regiment (P Coy) | B7: power | C7: Broad Jump | D7: m | E7: higher-is-better | F7: =IFERROR(VLOOKUP("UK Parachute Regiment (P Coy)",'Strength by pathway'!$A:$AG,26,FALSE),"—") | G7: =IFERROR(VLOOKUP("UK Parachute Regiment (P Coy)",'Strength by pathway'!$A:$AG,27,FALSE),"—") | H7: =IFERROR(VLOOKUP("UK Parachute Regiment (P Coy)",'Strength by pathway'!$A:$AG,28,FALSE),"—") | I7: =IFERROR(VLOOKUP("UK Parachute Regiment (P Coy)",'Strength by pathway'!$A:$AG,29,FALSE),"—")
A8: UK Parachute Regiment (P Coy) | B8: grip | C8: Dead hang (grip) | D8: sec | E8: higher-is-better | F8: =IFERROR(VLOOKUP("UK Parachute Regiment (P Coy)",'Strength by pathway'!$A:$AG,30,FALSE),"—") | G8: =IFERROR(VLOOKUP("UK Parachute Regiment (P Coy)",'Strength by pathway'!$A:$AG,31,FALSE),"—") | H8: =IFERROR(VLOOKUP("UK Parachute Regiment (P Coy)",'Strength by pathway'!$A:$AG,32,FALSE),"—") | I8: =IFERROR(VLOOKUP("UK Parachute Regiment (P Coy)",'Strength by pathway'!$A:$AG,33,FALSE),"—")
A9: UK Parachute Regiment (P Coy) | B9: upper_endurance | C9: Pull-ups (no time) | D9: reps | E9: higher-is-better | F9: 5 | G9: 8 | H9: 12 | I9: 20
A10: UK Parachute Regiment (P Coy) | B10: upper_endurance | C10: Push-ups (2 min) | D10: reps | E10: higher-is-better | F10: 25 | G10: 40 | H10: 60 | I10: 80
A11: UK Parachute Regiment (P Coy) | B11: core_endurance | C11: Sit-ups (2 min) | D11: reps | E11: higher-is-better | F11: 30 | G11: 50 | H11: 65 | I11: 80
A12: UK Parachute Regiment (P Coy) | B12: running | C12: 1.5-mile run | D12: sec | E12: lower-is-better | F12: 10:00 | G12: 9:30 | H12: 8:40 | I12: 8:00
A13: UK Parachute Regiment (P Coy) | B13: rucking | C13: 10-mile ruck | D13: sec | E13: lower-is-better | F13: 1:50 | G13: 1:45 | H13: 1:40 | I13: 0.065972222
A14: UK Parachute Regiment (P Coy) | B14: stability | C14: Plank (front) | D14: sec | E14: higher-is-better | F14: 1:30 | G14: 2:30 | H14: 3:30 | I14: 4:30
A15: UK Parachute Regiment (P Coy) | B15: stability | C15: Side plank (per side) | D15: sec | E15: higher-is-better | F15: 1:00 | G15: 1:30 | H15: 2:00 | I15: 3:00
A16: UK Royal Marines (Cdo Course) | B16: lower_strength | C16: Back Squat | D16: kg | E16: higher-is-better | F16: =IFERROR(VLOOKUP("UK Royal Marines (Cdo Course)",'Strength by pathway'!$A:$AG,2,FALSE),"—") | G16: =IFERROR(VLOOKUP("UK Royal Marines (Cdo Course)",'Strength by pathway'!$A:$AG,3,FALSE),"—") | H16: =IFERROR(VLOOKUP("UK Royal Marines (Cdo Course)",'Strength by pathway'!$A:$AG,4,FALSE),"—") | I16: =IFERROR(VLOOKUP("UK Royal Marines (Cdo Course)",'Strength by pathway'!$A:$AG,5,FALSE),"—") | K16: synced 2026-05-21 from benchmark_tests.ts
A17: UK Royal Marines (Cdo Course) | B17: lower_strength | C17: Hex-bar DL | D17: kg | E17: higher-is-better | F17: =IFERROR(VLOOKUP("UK Royal Marines (Cdo Course)",'Strength by pathway'!$A:$AG,6,FALSE),"—") | G17: =IFERROR(VLOOKUP("UK Royal Marines (Cdo Course)",'Strength by pathway'!$A:$AG,7,FALSE),"—") | H17: =IFERROR(VLOOKUP("UK Royal Marines (Cdo Course)",'Strength by pathway'!$A:$AG,8,FALSE),"—") | I17: =IFERROR(VLOOKUP("UK Royal Marines (Cdo Course)",'Strength by pathway'!$A:$AG,9,FALSE),"—")
A18: UK Royal Marines (Cdo Course) | B18: lower_strength | C18: Conventional DL | D18: kg | E18: higher-is-better | F18: =IFERROR(VLOOKUP("UK Royal Marines (Cdo Course)",'Strength by pathway'!$A:$AG,10,FALSE),"—") | G18: =IFERROR(VLOOKUP("UK Royal Marines (Cdo Course)",'Strength by pathway'!$A:$AG,11,FALSE),"—") | H18: =IFERROR(VLOOKUP("UK Royal Marines (Cdo Course)",'Strength by pathway'!$A:$AG,12,FALSE),"—") | I18: =IFERROR(VLOOKUP("UK Royal Marines (Cdo Course)",'Strength by pathway'!$A:$AG,13,FALSE),"—")
A19: UK Royal Marines (Cdo Course) | B19: upper_strength | C19: Bench Press | D19: kg | E19: higher-is-better | F19: =IFERROR(VLOOKUP("UK Royal Marines (Cdo Course)",'Strength by pathway'!$A:$AG,14,FALSE),"—") | G19: =IFERROR(VLOOKUP("UK Royal Marines (Cdo Course)",'Strength by pathway'!$A:$AG,15,FALSE),"—") | H19: =IFERROR(VLOOKUP("UK Royal Marines (Cdo Course)",'Strength by pathway'!$A:$AG,16,FALSE),"—") | I19: =IFERROR(VLOOKUP("UK Royal Marines (Cdo Course)",'Strength by pathway'!$A:$AG,17,FALSE),"—")
A20: UK Royal Marines (Cdo Course) | B20: power | C20: Power Clean | D20: kg | E20: higher-is-better | F20: =IFERROR(VLOOKUP("UK Royal Marines (Cdo Course)",'Strength by pathway'!$A:$AG,22,FALSE),"—") | G20: =IFERROR(VLOOKUP("UK Royal Marines (Cdo Course)",'Strength by pathway'!$A:$AG,23,FALSE),"—") | H20: =IFERROR(VLOOKUP("UK Royal Marines (Cdo Course)",'Strength by pathway'!$A:$AG,24,FALSE),"—") | I20: =IFERROR(VLOOKUP("UK Royal Marines (Cdo Course)",'Strength by pathway'!$A:$AG,25,FALSE),"—")
A21: UK Royal Marines (Cdo Course) | B21: power | C21: Broad Jump | D21: m | E21: higher-is-better | F21: =IFERROR(VLOOKUP("UK Royal Marines (Cdo Course)",'Strength by pathway'!$A:$AG,26,FALSE),"—") | G21: =IFERROR(VLOOKUP("UK Royal Marines (Cdo Course)",'Strength by pathway'!$A:$AG,27,FALSE),"—") | H21: =IFERROR(VLOOKUP("UK Royal Marines (Cdo Course)",'Strength by pathway'!$A:$AG,28,FALSE),"—") | I21: =IFERROR(VLOOKUP("UK Royal Marines (Cdo Course)",'Strength by pathway'!$A:$AG,29,FALSE),"—")
A22: UK Royal Marines (Cdo Course) | B22: grip | C22: Dead hang (grip) | D22: sec | E22: higher-is-better | F22: =IFERROR(VLOOKUP("UK Royal Marines (Cdo Course)",'Strength by pathway'!$A:$AG,30,FALSE),"—") | G22: =IFERROR(VLOOKUP("UK Royal Marines (Cdo Course)",'Strength by pathway'!$A:$AG,31,FALSE),"—") | H22: =IFERROR(VLOOKUP("UK Royal Marines (Cdo Course)",'Strength by pathway'!$A:$AG,32,FALSE),"—") | I22: =IFERROR(VLOOKUP("UK Royal Marines (Cdo Course)",'Strength by pathway'!$A:$AG,33,FALSE),"—")
A23: UK Royal Marines (Cdo Course) | B23: upper_endurance | C23: Pull-ups (no time) | D23: reps | E23: higher-is-better | F23: 8 | G23: 13 | H23: 18 | I23: 22
A24: UK Royal Marines (Cdo Course) | B24: upper_endurance | C24: Push-ups (2 min) | D24: reps | E24: higher-is-better | F24: 50 | G24: 65 | H24: 80 | I24: 100
A25: UK Royal Marines (Cdo Course) | B25: core_endurance | C25: Sit-ups (2 min) | D25: reps | E25: higher-is-better | F25: 50 | G25: 75 | H25: 90 | I25: 110
A26: UK Royal Marines (Cdo Course) | B26: running | C26: 1.5-mile run | D26: sec | E26: lower-is-better | F26: 10:30 | G26: 9:30 | H26: 9:00 | I26: 8:30
A27: UK Royal Marines (Cdo Course) | B27: rucking | C27: 30-mile ruck | D27: sec | E27: lower-is-better | F27: 8:00 | G27: 7:30 | H27: 7:00 | I27: 6:30
A28: UK Royal Marines (Cdo Course) | B28: stability | C28: Plank (front) | D28: sec | E28: higher-is-better | F28: 1:30 | G28: 2:30 | H28: 3:30 | I28: 4:30
A29: UK Royal Marines (Cdo Course) | B29: stability | C29: Side plank (per side) | D29: sec | E29: higher-is-better | F29: 1:00 | G29: 1:30 | H29: 2:00 | I29: 3:00
A30: US Marine Corps (PFT/CFT) | B30: lower_strength | C30: Back Squat | D30: kg | E30: higher-is-better | F30: =IFERROR(VLOOKUP("US Marine Corps (PFT/CFT)",'Strength by pathway'!$A:$AG,2,FALSE),"—") | G30: =IFERROR(VLOOKUP("US Marine Corps (PFT/CFT)",'Strength by pathway'!$A:$AG,3,FALSE),"—") | H30: =IFERROR(VLOOKUP("US Marine Corps (PFT/CFT)",'Strength by pathway'!$A:$AG,4,FALSE),"—") | I30: =IFERROR(VLOOKUP("US Marine Corps (PFT/CFT)",'Strength by pathway'!$A:$AG,5,FALSE),"—") | J30: Reverted — USMC ≠ RM-Cdo pattern; marines treated as separate role (2026-05-11) | K30: synced 2026-05-21 from benchmark_tests.ts
A31: US Marine Corps (PFT/CFT) | B31: lower_strength | C31: Hex-bar DL | D31: kg | E31: higher-is-better | F31: =IFERROR(VLOOKUP("US Marine Corps (PFT/CFT)",'Strength by pathway'!$A:$AG,6,FALSE),"—") | G31: =IFERROR(VLOOKUP("US Marine Corps (PFT/CFT)",'Strength by pathway'!$A:$AG,7,FALSE),"—") | H31: =IFERROR(VLOOKUP("US Marine Corps (PFT/CFT)",'Strength by pathway'!$A:$AG,8,FALSE),"—") | I31: =IFERROR(VLOOKUP("US Marine Corps (PFT/CFT)",'Strength by pathway'!$A:$AG,9,FALSE),"—") | J31: Reverted — USMC ≠ RM-Cdo pattern; marines treated as separate role (2026-05-11)
A32: US Marine Corps (PFT/CFT) | B32: lower_strength | C32: Conventional DL | D32: kg | E32: higher-is-better | F32: =IFERROR(VLOOKUP("US Marine Corps (PFT/CFT)",'Strength by pathway'!$A:$AG,10,FALSE),"—") | G32: =IFERROR(VLOOKUP("US Marine Corps (PFT/CFT)",'Strength by pathway'!$A:$AG,11,FALSE),"—") | H32: =IFERROR(VLOOKUP("US Marine Corps (PFT/CFT)",'Strength by pathway'!$A:$AG,12,FALSE),"—") | I32: =IFERROR(VLOOKUP("US Marine Corps (PFT/CFT)",'Strength by pathway'!$A:$AG,13,FALSE),"—") | J32: Reverted — USMC ≠ RM-Cdo pattern; marines treated as separate role (2026-05-11)
A33: US Marine Corps (PFT/CFT) | B33: upper_strength | C33: Bench Press | D33: kg | E33: higher-is-better | F33: =IFERROR(VLOOKUP("US Marine Corps (PFT/CFT)",'Strength by pathway'!$A:$AG,14,FALSE),"—") | G33: =IFERROR(VLOOKUP("US Marine Corps (PFT/CFT)",'Strength by pathway'!$A:$AG,15,FALSE),"—") | H33: =IFERROR(VLOOKUP("US Marine Corps (PFT/CFT)",'Strength by pathway'!$A:$AG,16,FALSE),"—") | I33: =IFERROR(VLOOKUP("US Marine Corps (PFT/CFT)",'Strength by pathway'!$A:$AG,17,FALSE),"—") | J33: Reverted — USMC ≠ RM-Cdo pattern; marines treated as separate role (2026-05-11)
A34: US Marine Corps (PFT/CFT) | B34: power | C34: Power Clean | D34: kg | E34: higher-is-better | F34: =IFERROR(VLOOKUP("US Marine Corps (PFT/CFT)",'Strength by pathway'!$A:$AG,22,FALSE),"—") | G34: =IFERROR(VLOOKUP("US Marine Corps (PFT/CFT)",'Strength by pathway'!$A:$AG,23,FALSE),"—") | H34: =IFERROR(VLOOKUP("US Marine Corps (PFT/CFT)",'Strength by pathway'!$A:$AG,24,FALSE),"—") | I34: =IFERROR(VLOOKUP("US Marine Corps (PFT/CFT)",'Strength by pathway'!$A:$AG,25,FALSE),"—") | J34: Reverted — USMC ≠ RM-Cdo pattern; marines treated as separate role (2026-05-11)
A35: US Marine Corps (PFT/CFT) | B35: power | C35: Broad Jump | D35: m | E35: higher-is-better | F35: =IFERROR(VLOOKUP("US Marine Corps (PFT/CFT)",'Strength by pathway'!$A:$AG,26,FALSE),"—") | G35: =IFERROR(VLOOKUP("US Marine Corps (PFT/CFT)",'Strength by pathway'!$A:$AG,27,FALSE),"—") | H35: =IFERROR(VLOOKUP("US Marine Corps (PFT/CFT)",'Strength by pathway'!$A:$AG,28,FALSE),"—") | I35: =IFERROR(VLOOKUP("US Marine Corps (PFT/CFT)",'Strength by pathway'!$A:$AG,29,FALSE),"—") | J35: Auto-adjusted from user patterns (2026-05-11)
A36: US Marine Corps (PFT/CFT) | B36: grip | C36: Dead hang (grip) | D36: sec | E36: higher-is-better | F36: =IFERROR(VLOOKUP("US Marine Corps (PFT/CFT)",'Strength by pathway'!$A:$AG,30,FALSE),"—") | G36: =IFERROR(VLOOKUP("US Marine Corps (PFT/CFT)",'Strength by pathway'!$A:$AG,31,FALSE),"—") | H36: =IFERROR(VLOOKUP("US Marine Corps (PFT/CFT)",'Strength by pathway'!$A:$AG,32,FALSE),"—") | I36: =IFERROR(VLOOKUP("US Marine Corps (PFT/CFT)",'Strength by pathway'!$A:$AG,33,FALSE),"—") | J36: Lowered below UK equivalent per role-bar framing (2026-05-11)
A37: US Marine Corps (PFT/CFT) | B37: upper_endurance | C37: Pull-ups (no time) | D37: reps | E37: higher-is-better | F37: 3 | G37: 12 | H37: 23 | I37: 23
A38: US Marine Corps (PFT/CFT) | B38: upper_endurance | C38: Push-ups (2 min) | D38: reps | E38: higher-is-better | F38: 42 | G38: 60 | H38: 87 | I38: 87
A39: US Marine Corps (PFT/CFT) | B39: running | C39: 3-mile run | D39: sec | E39: lower-is-better | F39: 27:40 | G39: 21:00 | H39: 18:00 | I39: 18:00
A40: US Marine Corps (PFT/CFT) | B40: stability | C40: Plank (front) | D40: sec | E40: higher-is-better | F40: 1:03 | G40: 3:00 | H40: 3:45 | I40: 3:45
...

Sheet Weights
A1: Pathway | B1: running | C1: rucking | D1: swimming | E1: lower_strength | F1: upper_strength | G1: upper_endurance | H1: core_endurance | I1: stability | J1: grip | K1: power | L1: SUM
A2: UK Parachute Regiment (P Coy) | B2: 30 | C2: 30 | D2: 0 | E2: 10 | F2: 5 | G2: 10 | H2: 5 | I2: 10 | J2: 0 | K2: 0 | L2: =SUM(B2:K2)
A3: UK Royal Marines (Cdo Course) | B3: 15 | C3: 15 | D3: 5 | E3: 10 | F3: 5 | G3: 15 | H3: 10 | I3: 15 | J3: 5 | K3: 5 | L3: =SUM(B3:K3)
A4: US Marine Corps (PFT/CFT) | B4: 25 | C4: 10 | D4: 0 | E4: 10 | F4: 5 | G4: 25 | H4: 10 | I4: 15 | J4: 0 | K4: 0 | L4: =SUM(B4:K4)
A5: US Army Airborne | B5: 25 | C5: 25 | D5: 0 | E5: 10 | F5: 5 | G5: 15 | H5: 10 | I5: 10 | J5: 0 | K5: 0 | L5: =SUM(B5:K5)
A6: Navy SEAL (BUD/S) | B6: 20 | C6: 0 | D6: 25 | E6: 5 | F6: 5 | G6: 20 | H6: 15 | I6: 10 | J6: 0 | K6: 0 | L6: =SUM(B6:K6)
A7: USAF Pararescue (PJ) | B7: 20 | C7: 10 | D7: 30 | E7: 10 | F7: 0 | G7: 15 | H7: 5 | I7: 10 | J7: 0 | K7: 0 | L7: =SUM(B7:K7)
A8: US Army Special Forces (SFAS) | B8: 10 | C8: 25 | D8: 0 | E8: 15 | F8: 10 | G8: 15 | H8: 5 | I8: 10 | J8: 5 | K8: 5 | L8: =SUM(B8:K8)
A9: UK Special Forces (SAS/SBS) | B9: 10 | C9: 30 | D9: 0 | E9: 10 | F9: 5 | G9: 15 | H9: 5 | I9: 20 | J9: 5 | K9: 0 | L9: =SUM(B9:K9)
A10: Tactical (generic) | B10: 25 | C10: 10 | D10: 0 | E10: 20 | F10: 20 | G10: 10 | H10: 5 | I10: 5 | J10: 0 | K10: 5 | L10: =SUM(B10:K10)
A12: Weights for grip + power are placeholders — Phase 12 will rebalance the existing tables.
A13: Police PT | B13: 25 | C13: 0 | D13: 0 | E13: 10 | F13: 5 | G13: 25 | H13: 10 | I13: 10 | J13: 10 | K13: 5 | L13: =SUM(B13:K13)
A14: SWAT / Tactical Team | B14: 15 | C14: 0 | D14: 0 | E14: 15 | F14: 10 | G14: 20 | H14: 5 | I14: 15 | J14: 10 | K14: 10 | L14: =SUM(B14:K14)
A15: US Army | B15: 20 | C15: 15 | D15: 0 | E15: 10 | F15: 5 | G15: 20 | H15: 10 | I15: 10 | J15: 5 | K15: 5 | L15: =SUM(B15:K15)
A16: US Infantry | B16: 15 | C16: 25 | D16: 0 | E16: 15 | F16: 5 | G16: 20 | H16: 5 | I16: 10 | J16: 5 | K16: 0 | L16: =SUM(B16:K16)
A17: UK Army | B17: 20 | C17: 15 | D17: 0 | E17: 10 | F17: 5 | G17: 20 | H17: 10 | I17: 10 | J17: 5 | K17: 5 | L17: =SUM(B17:K17)
A18: UK Infantry | B18: 15 | C18: 25 | D18: 0 | E18: 15 | F18: 5 | G18: 20 | H18: 5 | I18: 10 | J18: 5 | K18: 0 | L18: =SUM(B18:K18)

Sheet Pathway context
A1: Pathway | B1: Typical BW | C1: Carry load | D1: Primary demands
A2: UK Parachute Regiment (P Coy) | B2: 75-85 kg | C2: 35 lb bergen | D2: Light + fast + endurance dominant
A3: UK Royal Marines (Cdo Course) | B3: 78-86 kg | C3: 32 lb load | D3: Light + upper-body (rope, climbs, 30-miler)
A4: US Marine Corps (PFT/CFT) | B4: 80-90 kg | C4: 35-45 lb | D4: Balanced infantry / amphibious
A5: US Army Airborne | B5: 82-90 kg | C5: 35-45 lb | D5: Paratrooper + PLF landings
A6: Navy SEAL (BUD/S) | B6: 80-90 kg | C6: aquatic | D6: Swim + upper-body endurance dominant
A7: USAF Pararescue (PJ) | B7: 78-86 kg | C7: 25-30 lb | D7: Aquatic athlete + jump landings
A8: US Army Special Forces (SFAS) | B8: 85-95 kg | C8: 45-50 lb | D8: Heavy ruck + all-rounder
A9: UK Special Forces (SAS/SBS) | B9: 80-90 kg | C9: 55 lb | D9: Heaviest carriage + all-rounder
A10: Tactical (generic) | B10: 80-90 kg | C10: 35 lb | D10: Balanced middle ground

Sheet Strength by pathway
A1: Pathway | B1: Back Squat (Pass) | C1: Back Squat (Good) | D1: Back Squat (Excellent) | E1: Back Squat (Elite) | F1: Hex-bar DL (Pass) | G1: Hex-bar DL (Good) | H1: Hex-bar DL (Excellent) | I1: Hex-bar DL (Elite) | J1: Conventional DL (Pass) | K1: Conventional DL (Good) | L1: Conventional DL (Excellent) | M1: Conventional DL (Elite) | N1: Bench Press (Pass) | O1: Bench Press (Good) | P1: Bench Press (Excellent) | Q1: Bench Press (Elite) | R1: Overhead Press (Pass) | S1: Overhead Press (Good) | T1: Overhead Press (Excellent) | U1: Overhead Press (Elite) | V1: Power Clean (Pass) | W1: Power Clean (Good) | X1: Power Clean (Excellent) | Y1: Power Clean (Elite) | Z1: Broad Jump (Pass) | AA1: Broad Jump (Good) | AB1: Broad Jump (Excellent) | AC1: Broad Jump (Elite) | AD1: Dead hang (grip) (Pass) | AE1: Dead hang (grip) (Good) | AF1: Dead hang (grip) (Excellent) | AG1: Dead hang (grip) (Elite)
A2: UK Parachute Regiment (P Coy) | B2: 80 | C2: =B2+30 | D2: =C2+20 | E2: =D2+20 | F2: =B2+25 | G2: =F2+35 | H2: =G2+25 | I2: =H2+20 | J2: =F2-10 | K2: =J2+30 | L2: =K2+20 | M2: =L2+20 | N2: 75 | O2: 95 | P2: 115 | Q2: 135 | R2: — | S2: — | T2: — | U2: — | V2: 55 | W2: 75 | X2: 90 | Y2: 110 | Z2: 2.05 | AA2: 2.35 | AB2: 2.6 | AC2: 2.85 | AD2: 0:30 | AE2: 1:00 | AF2: 1:30 | AG2: 2:00
A3: UK Royal Marines (Cdo Course) | B3: 110 | C3: =B3+30 | D3: =C3+20 | E3: =D3+20 | F3: =B3+25 | G3: =F3+35 | H3: =G3+25 | I3: =H3+20 | J3: =F3-10 | K3: =J3+30 | L3: =K3+20 | M3: =L3+20 | N3: 80 | O3: 100 | P3: 120 | Q3: 140 | R3: — | S3: — | T3: — | U3: — | V3: 60 | W3: 80 | X3: 95 | Y3: 115 | Z3: 2.05 | AA3: 2.35 | AB3: 2.6 | AC3: 2.85 | AD3: 0:35 | AE3: 1:00 | AF3: 1:30 | AG3: 2:00
A4: US Marine Corps (PFT/CFT) | B4: 100 | C4: =B4+30 | D4: =C4+20 | E4: =D4+20 | F4: =B4+25 | G4: =F4+35 | H4: =G4+25 | I4: =H4+20 | J4: =F4-10 | K4: =J4+30 | L4: =K4+20 | M4: =L4+20 | N4: 80 | O4: 100 | P4: 120 | Q4: 140 | R4: — | S4: — | T4: — | U4: — | V4: 65 | W4: 85 | X4: 100 | Y4: 120 | Z4: 2.1 | AA4: 2.4 | AB4: 2.65 | AC4: 2.9 | AD4: 0:40 | AE4: 1:05 | AF4: 1:35 | AG4: 2:00
A5: US Army Airborne | B5: 95 | C5: =B5+30 | D5: =C5+20 | E5: =D5+20 | F5: =B5+25 | G5: =F5+35 | H5: =G5+25 | I5: =H5+20 | J5: =F5-10 | K5: =J5+30 | L5: =K5+20 | M5: =L5+20 | N5: 80 | O5: 100 | P5: 120 | Q5: 135 | R5: — | S5: — | T5: — | U5: — | V5: 70 | W5: 90 | X5: 105 | Y5: 125 | Z5: 2.15 | AA5: 2.45 | AB5: 2.7 | AC5: 2.95 | AD5: 0:40 | AE5: 1:05 | AF5: 1:35 | AG5: 2:00
A6: Navy SEAL (BUD/S) | B6: 100 | C6: =B6+30 | D6: =C6+20 | E6: =D6+20 | F6: =B6+25 | G6: =F6+35 | H6: =G6+25 | I6: =H6+20 | J6: =F6-10 | K6: =J6+30 | L6: =K6+20 | M6: =L6+20 | N6: 80 | O6: 100 | P6: 120 | Q6: 140 | R6: — | S6: — | T6: — | U6: — | V6: 65 | W6: 85 | X6: 100 | Y6: 120 | Z6: 2.1 | AA6: 2.4 | AB6: 2.65 | AC6: 2.9 | AD6: 0:45 | AE6: 1:15 | AF6: 1:50 | AG6: 2:30
A7: USAF Pararescue (PJ) | B7: 95 | C7: =B7+30 | D7: =C7+20 | E7: =D7+20 | F7: =B7+25 | G7: =F7+35 | H7: =G7+25 | I7: =H7+20 | J7: =F7-10 | K7: =J7+30 | L7: =K7+20 | M7: =L7+20 | N7: 75 | O7: 95 | P7: 115 | Q7: 135 | R7: — | S7: — | T7: — | U7: — | V7: 60 | W7: 80 | X7: 95 | Y7: 110 | Z7: 2.05 | AA7: 2.35 | AB7: 2.6 | AC7: 2.85 | AD7: 0:45 | AE7: 1:15 | AF7: 1:45 | AG7: 2:20
A8: US Army Special Forces (SFAS) | B8: 110 | C8: =B8+30 | D8: =C8+20 | E8: =D8+20 | F8: =B8+25 | G8: =F8+35 | H8: =G8+25 | I8: =H8+20 | J8: =F8-10 | K8: =J8+30 | L8: =K8+20 | M8: =L8+20 | N8: 90 | O8: 110 | P8: 130 | Q8: 155 | R8: 50 | S8: 70 | T8: 90 | U8: 105 | V8: 80 | W8: 100 | X8: 120 | Y8: 140 | Z8: 2.2 | AA8: 2.5 | AB8: 2.75 | AC8: 3 | AD8: 0:45 | AE8: 1:10 | AF8: 1:40 | AG8: 2:10
A9: UK Special Forces (SAS/SBS) | B9: 100 | C9: =B9+30 | D9: =C9+20 | E9: =D9+20 | F9: =B9+25 | G9: =F9+35 | H9: =G9+25 | I9: =H9+20 | J9: =F9-10 | K9: =J9+30 | L9: =K9+20 | M9: =L9+20 | N9: 90 | O9: 110 | P9: 130 | Q9: 150 | R9: — | S9: — | T9: — | U9: — | V9: 80 | W9: 100 | X9: 120 | Y9: 135 | Z9: 2.25 | AA9: 2.55 | AB9: 2.8 | AC9: 3.05 | AD9: 0:45 | AE9: 1:10 | AF9: 1:40 | AG9: 2:10
A10: Tactical (generic) | B10: 105 | C10: =B10+30 | D10: =C10+20 | E10: =D10+20 | F10: =B10+25 | G10: =F10+35 | H10: =G10+25 | I10: =H10+20 | J10: =F10-10 | K10: =J10+30 | L10: =K10+20 | M10: =L10+20 | N10: 80 | O10: 105 | P10: 125 | Q10: 145 | R10: — | S10: — | T10: — | U10: — | V10: 70 | W10: 90 | X10: 110 | Y10: 125 | Z10: 2.1 | AA10: 2.4 | AB10: 2.65 | AC10: 2.9 | AD10: 0:40 | AE10: 1:05 | AF10: 1:35 | AG10: 2:00
A11: Police PT | B11: 80 | C11: 100 | D11: 120 | E11: 140 | F11: 100 | G11: 125 | H11: 150 | I11: 170 | J11: 90 | K11: 115 | L11: 140 | M11: 160 | N11: 65 | O11: 80 | P11: 95 | Q11: 110 | R11: — | S11: — | T11: — | U11: — | V11: 45 | W11: 60 | X11: 75 | Y11: 90 | Z11: 1.7 | AA11: 1.9 | AB11: 2.1 | AC11: 2.3 | AD11: 0:30 | AE11: 0:50 | AF11: 1:15 | AG11: 1:40
A12: SWAT / Tactical Team | B12: 100 | C12: 125 | D12: 150 | E12: 175 | F12: 130 | G12: 160 | H12: 185 | I12: 210 | J12: 115 | K12: 145 | L12: 170 | M12: 195 | N12: 80 | O12: 100 | P12: 120 | Q12: 140 | R12: 50 | S12: 65 | T12: 80 | U12: 95 | V12: 65 | W12: 85 | X12: 100 | Y12: 120 | Z12: 1.9 | AA12: 2.1 | AB12: 2.3 | AC12: 2.5 | AD12: 0:45 | AE12: 1:15 | AF12: 1:40 | AG12: 2:10
A13: US Army | B13: 80 | C13: 105 | D13: 130 | E13: 155 | F13: 100 | G13: 130 | H13: 160 | I13: 185 | J13: 90 | K13: 115 | L13: 145 | M13: 170 | N13: 60 | O13: 80 | P13: 100 | Q13: 120 | R13: — | S13: — | T13: — | U13: — | V13: 50 | W13: 70 | X13: 90 | Y13: 110 | Z13: 1.7 | AA13: 1.9 | AB13: 2.1 | AC13: 2.3 | AD13: 0:30 | AE13: 0:50 | AF13: 1:15 | AG13: 1:40
A14: US Infantry | B14: 100 | C14: 130 | D14: 155 | E14: 175 | F14: 120 | G14: 155 | H14: 185 | I14: 210 | J14: 110 | K14: 140 | L14: 170 | M14: 195 | N14: 75 | O14: 95 | P14: 115 | Q14: 135 | R14: — | S14: — | T14: — | U14: — | V14: — | W14: — | X14: — | Y14: — | Z14: — | AA14: — | AB14: — | AC14: — | AD14: 0:35 | AE14: 1:00 | AF14: 1:30 | AG14: 2:00
A15: UK Army | B15: 80 | C15: 105 | D15: 130 | E15: 155 | F15: 100 | G15: 130 | H15: 160 | I15: 185 | J15: 90 | K15: 115 | L15: 145 | M15: 170 | N15: 60 | O15: 80 | P15: 100 | Q15: 120 | R15: — | S15: — | T15: — | U15: — | V15: 50 | W15: 70 | X15: 90 | Y15: 110 | Z15: 1.7 | AA15: 1.9 | AB15: 2.1 | AC15: 2.3 | AD15: 0:30 | AE15: 0:50 | AF15: 1:15 | AG15: 1:40
A16: UK Infantry | B16: 100 | C16: 130 | D16: 155 | E16: 175 | F16: 120 | G16: 155 | H16: 185 | I16: 210 | J16: 110 | K16: 140 | L16: 170 | M16: 195 | N16: 75 | O16: 95 | P16: 115 | Q16: 135 | R16: — | S16: — | T16: — | U16: — | V16: — | W16: — | X16: — | Y16: — | Z16: — | AA16: — | AB16: — | AC16: — | AD16: 0:35 | AE16: 1:00 | AF16: 1:30 | AG16: 2:00
